Workbook
Name Ausgewählte_Kriterien: '[1]Bewertung der Kriterien'!$A$2:$A$8

Sheet Datenbasis
A1: Datenbasis für die Nutzwertanalyse | D1: Datum: | E1: 41713 | G1: Tipp
D2: Version: | E2: 1.0
A3: Projekt: | B3: Auswahl eines Produktions-Planungssystems (ERP)
A5: Zielsetzung:
A6: Auswahl eines Beratungsunternehmens für das Auswahlverfahren
A7: Beschreibung des Auswahlverfahrens
A8: Für die externe Begleitung bei der Auswahl einer ERP-Software für das Unternehmen M.GmbH stehen drei Beratungsunternehmen zur Auswahl. Die Entscheidung für einen Berater hat eine große Tragweite, da die Auswahl eines Systems für das Unternehmen von großer Wichtigkeit ist: Das ERP-System, das ausgesucht wird, soll die nächsten Jahre alle wesentlichen Prozesse im Unternehmen abbilden und den sich verändernden Bedürfnissen anpassen können. Da das Know-how im eigenen Hause nicht vorhanden ist, wird erwartet, dass ein Beratungsunternehmen die Anforderungen an eine für die M.GmbH optimale Lösung definieren kann und das Projektteam beim Auswahlprozess optimal unterstützt.
A10: Kostenbudget:
A11: Da keine Erfahrungen vorliegen, wieviele PT zu erwarten sind, ist kein Gesamtbudget vorgegeben;
A12: Nach Vorgabe des Controllings sollte der Tagessatz nicht über 2000 €/PT liegen.
A13: Zeitlimits:
A14: Ein optimaler Zeitplan für das Auswahlverfahren wird mit vier Monaten angesetzt (lt. Geschäftsführung)
A16: Alternativen
A17: Alternative 1: | B17: A BeratungsAG
A18: Alternative 2: | B18: B Consulting
A19: Alternative 3: | B19: Institut C
A20: Alternative 4: | B20: -
A21: Alternative 5: | B21: -

Sheet Kriterien und Gewichtung
A1: Kriterien für die Entscheidung | D1: =Datenbasis!B3 -> Auswahl eines Produktions-Planungssystems (ERP) | N1: =Datenbasis!D1 -> Datum: | O1: =Datenbasis!E1 -> 41713 | Q1: Tipp
D2: =Datenbasis!A6 -> Auswahl eines Beratungsunternehmens für das Auswahlverfahren | N2: =Datenbasis!D2 -> Version: | O2: =Datenbasis!E2 -> 1.0
A3: Tabelle der Entscheidungskriterien
A4: Nr. | B4: Kriterium | C4: Wichtig-keit | D4: Bemerkung
A5: 1 | B5: Unabhängigkeit | C5: hoch | D5: Das Unternehmen ist unabhängig von einem ERP-Hersteller
A6: 2 | B6: Gesamteindruck | C6: sehr hoch | D6: Gesamteindruck, den die Firma erzielt hat (Angebot, Präsentation, etc.)
A7: 3 | B7: Einzelkompetenz | C7: sehr hoch | D7: Erfahrung, Kompetenz der einzusetzenden Berater
A8: 4 | B8: Laufzeit | C8: hoch | D8: Geschätzte Laufzeit des Projekts
A9: 5 | B9: Kosten/PT | C9: sehr hoch | D9: Kosten pro Personentag (PT) / Berater (inkl. Anfahrt und Spesen)
A10: 6 | C10: K.O. | D10: Ähnliche Referenzprojekte liegen vor (muss erfüllt sein)
A11: 7
A12: 8
A13: 9
A14: 10
A17: Ermittlung der Gewichtungsfaktoren
A18: Kriterium | C18: =A19 -> 1 | D18: =A20 -> 2 | E18: =A21 -> 3 | F18: =A22 -> 4 | G18: =A23 -> 5 | H18: =A24 -> 6 | I18: =A25 -> 7 | J18: =A26 -> 8 | K18: =A27 -> 9 | L18: =A28 -> 10 | M18: Wert | N18: Faktor
A19: =A5 -> 1 | B19: =B5 -> Unabhängigkeit | D19: 1 | E19: 0 | F19: 1 | G19: 1 | M19: =SUM(C19:L19) -> 3 | N19: =ROUND(M19/$M$29,2) -> 0.15
A20: =A6 -> 2 | B20: =B6 -> Gesamteindruck | C20: =IF(D19=2,0,IF(D19=1,1,IF(D19=0,2,0))) -> 1 | E20: 1 | F20: 2 | G20: 1 | M20: =SUM(C20:L20) -> 5 | N20: =ROUND(M20/$M$29,2) -> 0.25
A21: =A7 -> 3 | B21: =B7 -> Einzelkompetenz | C21: =IF(E19=2,0,IF(E19=1,1,IF(E19=0,2,0))) -> 2 | D21: =IF(E20=2,0,IF(E20=1,1,IF(E20=0,2,0))) -> 1 | F21: 1 | G21: 2 | M21: =SUM(C21:L21) -> 6 | N21: =ROUND(M21/$M$29,2) -> 0.3
A22: =A8 -> 4 | B22: =B8 -> Laufzeit | C22: =IF(F19=2,0,IF(F19=1,1,IF(F19=0,2,0))) -> 1 | D22: =IF(F20=2,0,IF(F20=1,1,IF(F20=0,2,0))) -> 0 | E22: =IF(F21=2,0,IF(F21=1,1,IF(F21=0,2,0))) -> 1 | G22: 1 | M22: =SUM(C22:L22) -> 3 | N22: =ROUND(M22/$M$29,2) -> 0.15
A23: =A9 -> 5 | B23: =B9 -> Kosten/PT | C23: =IF(G19=2,0,IF(G19=1,1,IF(G19=0,2,0))) -> 1 | D23: =IF(G20=2,0,IF(G20=1,1,IF(G20=0,2,0))) -> 1 | E23: =IF(G21=2,0,IF(G21=1,1,IF(G21=0,2,0))) -> 0 | F23: =IF(G22=2,0,IF(G22=1,1,IF(G22=0,2,0))) -> 1 | M23: =SUM(C23:L23) -> 3 | N23: =ROUND(M23/$M$29,2) -> 0.15
A24: =A10 -> 6 | B24: =B10 -> 0 | C24: =IF(H19=2,0,IF(H19=1,1,IF(H19=0,2,0))) -> 2 | D24: =IF(H20=2,0,IF(H20=1,1,IF(H20=0,2,0))) -> 2 | E24: =IF(H21=2,0,IF(H21=1,1,IF(H21=0,2,0))) -> 2 | F24: =IF(H22=2,0,IF(H22=1,1,IF(H22=0,2,0))) -> 2 | G24: =IF(H23=2,0,IF(H23=1,1,IF(H23=0,2,0))) -> 2 | M24: =IF(B24=0,0,SUM(C24:L24)) -> 0 | N24: =ROUND(M24/$M$29,2) -> 0
A25: =A11 -> 7 | B25: =B11 -> 0 | C25: =IF(I19=2,0,IF(I19=1,1,IF(I19=0,2,0))) -> 2 | D25: =IF(I20=2,0,IF(I20=1,1,IF(I20=0,2,0))) -> 2 | E25: =IF(I21=2,0,IF(I21=1,1,IF(I21=0,2,0))) -> 2 | F25: =IF(I22=2,0,IF(I22=1,1,IF(I22=0,2,0))) -> 2 | G25: =IF(I23=2,0,IF(I23=1,1,IF(I23=0,2,0))) -> 2 | H25: =IF(I24=2,0,IF(I24=1,1,IF(I24=0,2,0))) -> 2 | M25: =IF(B25=0,0,SUM(C25:L25)) -> 0 | N25: =ROUND(M25/$M$29,2) -> 0
A26: =A12 -> 8 | B26: =B12 -> 0 | C26: =IF(J19=2,0,IF(J19=1,1,IF(J19=0,2,0))) -> 2 | D26: =IF(J20=2,0,IF(J20=1,1,IF(J20=0,2,0))) -> 2 | E26: =IF(J21=2,0,IF(J21=1,1,IF(J21=0,2,0))) -> 2 | F26: =IF(J22=2,0,IF(J22=1,1,IF(J22=0,2,0))) -> 2 | G26: =IF(J23=2,0,IF(J23=1,1,IF(J23=0,2,0))) -> 2 | H26: =IF(J24=2,0,IF(J24=1,1,IF(J24=0,2,0))) -> 2 | I26: =IF(J25=2,0,IF(J25=1,1,IF(J25=0,2,0))) -> 2 | M26: =IF(B26=0,0,SUM(C26:L26)) -> 0 | N26: =ROUND(M26/$M$29,2) -> 0
A27: =A13 -> 9 | B27: =B13 -> 0 | C27: =IF(K19=2,0,IF(K19=1,1,IF(K19=0,2,0))) -> 2 | D27: =IF(K20=2,0,IF(K20=1,1,IF(K20=0,2,0))) -> 2 | E27: =IF(K21=2,0,IF(K21=1,1,IF(K21=0,2,0))) -> 2 | F27: =IF(K22=2,0,IF(K22=1,1,IF(K22=0,2,0))) -> 2 | G27: =IF(K23=2,0,IF(K23=1,1,IF(K23=0,2,0))) -> 2 | H27: =IF(K24=2,0,IF(K24=1,1,IF(K24=0,2,0))) -> 2 | I27: =IF(K25=2,0,IF(K25=1,1,IF(K25=0,2,0))) -> 2 | J27: =IF(K26=2,0,IF(K26=1,1,IF(K26=0,2,0))) -> 2 | M27: =IF(B27=0,0,SUM(C27:L27)) -> 0 | N27: =ROUND(M27/$M$29,2) -> 0
A28: =A14 -> 10 | B28: =B14 -> 0 | C28: =IF(L19=2,0,IF(L19=1,1,IF(L19=0,2,0))) -> 2 | D28: =IF(L20=2,0,IF(L20=1,1,IF(L20=0,2,0))) -> 2 | E28: =IF(L21=2,0,IF(L21=1,1,IF(L21=0,2,0))) -> 2 | F28: =IF(L22=2,0,IF(L22=1,1,IF(L22=0,2,0))) -> 2 | G28: =IF(L23=2,0,IF(L23=1,1,IF(L23=0,2,0))) -> 2 | H28: =IF(L24=2,0,IF(L24=1,1,IF(L24=0,2,0))) -> 2 | I28: =IF(L25=2,0,IF(L25=1,1,IF(L25=0,2,0))) -> 2 | J28: =IF(L26=2,0,IF(L26=1,1,IF(L26=0,2,0))) -> 2 | K28: =IF(L27=2,0,IF(L27=1,1,IF(L27=0,2,0))) -> 2 | M28: =IF(B28=0,0,SUM(C28:L28)) -> 0 | N28: =ROUND(M28/$M$29,2) -> 0
B29: Summen | M29: =SUM(M19:M28) -> 20 | N29: =M29/$M$29 -> 1
C31: Legende: | E31: wichtiger im Vergleich zum Kriterium x = 2 Punkte
E32: gleiches Gewicht wie Kriterium x = 1 Punkt
E33: weniger wichtig als Kriterium x = 0
A35: Tabelle der Zielerfüllungsfaktoren | C35: Bewertung
A36: Nr. | B36: Kriterium | C36: schlecht (0-2 Punkte) | G36: mittel (3-5 Punkte) | K36: gut (6-8 Punkte)
A37: =A19 -> 1 | B37: =B19 -> Unabhängigkeit | C37: direkt an ein Systemhaus gebundene Firma | G37: einem Hersteller nahestehend | K37: völlig unabhängig, Institut einer Universität, Forschungsinstitut
A38: =A20 -> 2 | B38: =B20 -> Gesamteindruck | C38: sehr schlecht bis schlecht | G38: mittelmäßig | K38: gut bis sehr gut
A39: =A21 -> 3 | B39: =B21 -> Einzelkompetenz | C39: keine bis wenig | G39: mittelmäßig | K39: gut bis sehr gut
A40: =A22 -> 4 | B40: =B22 -> Laufzeit | C40: mehr als 6 Monate | G40: 5-6 Monate | K40: bis 4 Monate
A41: =A23 -> 5 | B41: =B23 -> Kosten/PT | C41: über 2.300€ | G41: 1.700 - 2.300€ | K41: unter 1.700€
A42: =A24 -> 6 | B42: =B24 -> 0
A43: =A25 -> 7 | B43: =B25 -> 0
A44: =A26 -> 8 | B44: =B26 -> 0
...

Sheet Bewertung - Nutzwert
A1: Ermittlung der Nutzwerte | C1: =Datenbasis!B3 -> Auswahl eines Produktions-Planungssystems (ERP) | L1: =Datenbasis!D1 -> Datum: | M1: =Datenbasis!E1 -> 41713 | O1: Tipp
C2: =Datenbasis!A6 -> Auswahl eines Beratungsunternehmens für das Auswahlverfahren | L2: =Datenbasis!D2 -> Version: | M2: =Datenbasis!E2 -> 1.0
B4: Bewertung der Alternativen | C4: Gewichtungs- faktor | D4: Bewertung nach Krit. | E4: Teil-Nutzwert | F4: Bewertung nach Krit. | G4: Teil-Nutzwert | H4: Bewertung nach Krit. | I4: Teil-Nutzwert | J4: Bewertung nach Krit. | K4: Teil-Nutzwert | L4: Bewertung nach Krit. | M4: Teil-Nutzwert
A5: Nr. | B5: Kriterium | D5: =Datenbasis!B17 -> A BeratungsAG | F5: =Datenbasis!B18 -> B Consulting | H5: =Datenbasis!B19 -> Institut C | J5: =Datenbasis!B20 -> - | L5: =Datenbasis!B21 -> -
A6: ='Kriterien und Gewichtung'!A5 -> 1 | B6: ='Kriterien und Gewichtung'!B5:I5 -> Unabhängigkeit | C6: ='Kriterien und Gewichtung'!N19 -> 0.15 | D6: 4 | E6: =ROUND($C6*D6,2) -> 0.6 | F6: 6 | G6: =ROUND($C6*F6,2) -> 0.9 | H6: 8 | I6: =ROUND($C6*H6,2) -> 1.2 | K6: =ROUND($C6*J6,2) -> 0 | M6: =ROUND($C6*L6,2) -> 0
A7: ='Kriterien und Gewichtung'!A6 -> 2 | B7: ='Kriterien und Gewichtung'!B6:I6 -> Gesamteindruck | C7: ='Kriterien und Gewichtung'!N20 -> 0.25 | D7: 7 | E7: =ROUND($C7*D7,2) -> 1.75 | F7: 6 | G7: =ROUND($C7*F7,2) -> 1.5 | H7: 6 | I7: =ROUND($C7*H7,2) -> 1.5 | K7: =ROUND($C7*J7,2) -> 0 | M7: =ROUND($C7*L7,2) -> 0
A8: ='Kriterien und Gewichtung'!A7 -> 3 | B8: ='Kriterien und Gewichtung'!B7:I7 -> Einzelkompetenz | C8: ='Kriterien und Gewichtung'!N21 -> 0.3 | D8: 6 | E8: =ROUND($C8*D8,2) -> 1.8 | F8: 8 | G8: =ROUND($C8*F8,2) -> 2.4 | H8: 7 | I8: =ROUND($C8*H8,2) -> 2.1 | K8: =ROUND($C8*J8,2) -> 0 | M8: =ROUND($C8*L8,2) -> 0
A9: ='Kriterien und Gewichtung'!A8 -> 4 | B9: ='Kriterien und Gewichtung'!B8:I8 -> Laufzeit | C9: ='Kriterien und Gewichtung'!N22 -> 0.15 | D9: 5 | E9: =ROUND($C9*D9,2) -> 0.75 | F9: 7 | G9: =ROUND($C9*F9,2) -> 1.05 | H9: 5 | I9: =ROUND($C9*H9,2) -> 0.75 | K9: =ROUND($C9*J9,2) -> 0 | M9: =ROUND($C9*L9,2) -> 0
A10: ='Kriterien und Gewichtung'!A9 -> 5 | B10: ='Kriterien und Gewichtung'!B9:I9 -> Kosten/PT | C10: ='Kriterien und Gewichtung'!N23 -> 0.15 | D10: 5 | E10: =ROUND($C10*D10,2) -> 0.75 | F10: 4 | G10: =ROUND($C10*F10,2) -> 0.6 | H10: 2 | I10: =ROUND($C10*H10,2) -> 0.3 | K10: =ROUND($C10*J10,2) -> 0 | M10: =ROUND($C10*L10,2) -> 0
A11: ='Kriterien und Gewichtung'!A10 -> 6 | B11: ='Kriterien und Gewichtung'!B10:I10 -> 0 | C11: ='Kriterien und Gewichtung'!N24 -> 0 | E11: =ROUND($C11*D11,2) -> 0 | G11: =ROUND($C11*F11,2) -> 0 | I11: =ROUND($C11*H11,2) -> 0 | K11: =ROUND($C11*J11,2) -> 0 | M11: =ROUND($C11*L11,2) -> 0
A12: ='Kriterien und Gewichtung'!A11 -> 7 | B12: ='Kriterien und Gewichtung'!A11:I11 -> 0 | C12: ='Kriterien und Gewichtung'!N25 -> 0 | E12: =ROUND($C12*D12,2) -> 0 | G12: =ROUND($C12*F12,2) -> 0 | I12: =ROUND($C12*H12,2) -> 0 | K12: =ROUND($C12*J12,2) -> 0 | M12: =ROUND($C12*L12,2) -> 0
A13: ='Kriterien und Gewichtung'!A12 -> 8 | B13: ='Kriterien und Gewichtung'!A12:I12 -> 0 | C13: ='Kriterien und Gewichtung'!N26 -> 0 | E13: =ROUND($C13*D13,2) -> 0 | G13: =ROUND($C13*F13,2) -> 0 | I13: =ROUND($C13*H13,2) -> 0 | K13: =ROUND($C13*J13,2) -> 0 | M13: =ROUND($C13*L13,2) -> 0
A14: ='Kriterien und Gewichtung'!A13 -> 9 | B14: ='Kriterien und Gewichtung'!A13:I13 -> 0 | C14: ='Kriterien und Gewichtung'!N27 -> 0 | E14: =ROUND($C14*D14,2) -> 0 | G14: =ROUND($C14*F14,2) -> 0 | I14: =ROUND($C14*H14,2) -> 0 | K14: =ROUND($C14*J14,2) -> 0 | M14: =ROUND($C14*L14,2) -> 0
A15: ='Kriterien und Gewichtung'!A14 -> 10 | B15: ='Kriterien und Gewichtung'!A14:I14 -> 0 | C15: ='Kriterien und Gewichtung'!N28 -> 0 | E15: =ROUND($C15*D15,2) -> 0 | G15: =ROUND($C15*F15,2) -> 0 | I15: =ROUND($C15*H15,2) -> 0 | K15: =ROUND($C15*J15,2) -> 0 | M15: =ROUND($C15*L15,2) -> 0
C16: Ergebnis | E16: =SUM(E6:E15) -> 5.65 | G16: =SUM(G6:G15) -> 6.45 | I16: =SUM(I6:I15) -> 5.85 | K16: =SUM(K6:K15) -> 0 | M16: =SUM(M6:M15) -> 0

Sheet Alt 1
A1: =Datenbasis!A3 -> Projekt: | F1: =Datenbasis!D1 -> Datum: | G1: =Datenbasis!E1 -> 41713
A2: =Datenbasis!B3 -> Auswahl eines Produktions-Planungssystems (ERP) | F2: =Datenbasis!D2 -> Version: | G2: =Datenbasis!E2 -> 1.0
A3: =Datenbasis!A6 -> Auswahl eines Beratungsunternehmens für das Auswahlverfahren
A5: =Datenbasis!A17 -> Alternative 1:
A7: Kurzbenennung: | B7: =Datenbasis!B17 -> A BeratungsAG
A9: Beschreibung:
A10: Seit 2010 mit der Firma in Geschäftskontakt. Bisher sehr guter Eindruck. Mitarbeiter: 18
A11: Noch keine Erfahrung mit sehr großen Projekten. Junges, engagiertes Team.
A12: Steht Hersteller xy sehr nahe; alle Projekte führten zur Einführung der Software B.
A13: Berater sind sehr kompetent und professionell
A14: Kundenreferenzen: einige (kleinere Projekte)
A16: Angebotsdaten:
A17: Angebot liegt vor, Beratertage 2.450€
A18: Laufzeit: 5 Monate geschätzt

Sheet Alt 2
A1: =Datenbasis!A3 -> Projekt: | F1: =Datenbasis!D1 -> Datum: | G1: =Datenbasis!E1 -> 41713
A2: =Datenbasis!B3 -> Auswahl eines Produktions-Planungssystems (ERP) | F2: =Datenbasis!D2 -> Version: | G2: =Datenbasis!E2 -> 1.0
A3: =Datenbasis!A6 -> Auswahl eines Beratungsunternehmens für das Auswahlverfahren
A5: =Datenbasis!A18 -> Alternative 2:
A7: Kurzbenennung: | B7: =Datenbasis!B18 -> B Consulting
A9: Beschreibung:
A10: Firma wurde empfohlen von Kunde Z. Bisher guter Eindruck. Mitarbeiter: 25
A11: Erfahrung mit kleinen und mittelgroßen Projekten.
A12: Erfahrenes Team, zwei Mitarbeiter und der Chef haben Auslandserfahrung, Kompetenz: ausgezeichnet
A14: Kundenreferenzen: drei genannte Kunden; davon einer in Frankreich. Zwei größere Aufträge
B15: Referenzen sind ausgezeichnet
A16: Angebotsdaten:
A17: Angebot liegt vor
A18: Laufzeit: 4-5 Monate geschätzt

Sheet Alt 3
A1: =Datenbasis!A3 -> Projekt: | F1: =Datenbasis!D1 -> Datum: | G1: =Datenbasis!E1 -> 41713
A2: =Datenbasis!B3 -> Auswahl eines Produktions-Planungssystems (ERP) | F2: =Datenbasis!D2 -> Version: | G2: =Datenbasis!E2 -> 1.0
A3: =Datenbasis!A6 -> Auswahl eines Beratungsunternehmens für das Auswahlverfahren
A5: =Datenbasis!A19 -> Alternative 3:
A7: Kurzbenennung: | B7: =Datenbasis!B19 -> Institut C
A9: Beschreibung:
A10: Institut wurde selbst recherchiert.
A11: Unabhängigkeit ist gesichert.
A12: Gesamteindruck ist sehr gut, ebenso die Kompetenz und Erfahrung der Berater.
A14: Kundenreferenzen: fünf genannte Kunden
A16: Angebotsdaten:
A17: Angebot liegt vor, PT liegt bei 1.700€
A18: Laufzeit: 6-7 Monate geschätzt

Sheet Alt 4
A1: =Datenbasis!A3 -> Projekt: | F1: =Datenbasis!D1 -> Datum: | G1: =Datenbasis!E1 -> 41713
A2: =Datenbasis!B3 -> Auswahl eines Produktions-Planungssystems (ERP) | F2: =Datenbasis!D2 -> Version: | G2: =Datenbasis!E2 -> 1.0
A3: =Datenbasis!A6 -> Auswahl eines Beratungsunternehmens für das Auswahlverfahren
A5: =Datenbasis!A20 -> Alternative 4:
A7: Kurzbenennung: | B7: =Datenbasis!B20 -> -
A9: Beschreibung:
A16: Angebotsdaten:

Sheet Alt 5
A1: =Datenbasis!A3 -> Projekt: | F1: =Datenbasis!D1 -> Datum: | G1: =Datenbasis!E1 -> 41713
A2: =Datenbasis!B3 -> Auswahl eines Produktions-Planungssystems (ERP) | F2: =Datenbasis!D2 -> Version: | G2: =Datenbasis!E2 -> 1.0
A3: =Datenbasis!A6 -> Auswahl eines Beratungsunternehmens für das Auswahlverfahren
A5: =Datenbasis!A21 -> Alternative 5:
A7: Kurzbenennung: | B7: =Datenbasis!B21 -> -
A9: Beschreibung:
A16: Angebotsdaten:

Sheet Grafik-Daten
A1: Daten für Grafik
B3: ='Bewertung - Nutzwert'!B4 -> Bewertung der Alternativen | C3: ='Bewertung - Nutzwert'!E4 -> Teil-Nutzwert | D3: ='Bewertung - Nutzwert'!G4 -> Teil-Nutzwert | E3: ='Bewertung - Nutzwert'!I4 -> Teil-Nutzwert | F3: ='Bewertung - Nutzwert'!K4 -> Teil-Nutzwert | G3: ='Bewertung - Nutzwert'!M4 -> Teil-Nutzwert
A4: ='Bewertung - Nutzwert'!A5 -> Nr. | B4: ='Bewertung - Nutzwert'!B5 -> Kriterium | C4: ='Bewertung - Nutzwert'!D5 -> A BeratungsAG | D4: ='Bewertung - Nutzwert'!F5 -> B Consulting | E4: ='Bewertung - Nutzwert'!H5 -> Institut C | F4: ='Bewertung - Nutzwert'!J5 -> - | G4: ='Bewertung - Nutzwert'!L5 -> -
A5: ='Bewertung - Nutzwert'!A6 -> 1 | B5: ='Bewertung - Nutzwert'!B6 -> Unabhängigkeit | C5: ='Bewertung - Nutzwert'!E6 -> 0.6 | D5: ='Bewertung - Nutzwert'!G6 -> 0.9 | E5: ='Bewertung - Nutzwert'!I6 -> 1.2 | F5: ='Bewertung - Nutzwert'!K6 -> 0 | G5: ='Bewertung - Nutzwert'!M6 -> 0
A6: ='Bewertung - Nutzwert'!A7 -> 2 | B6: ='Bewertung - Nutzwert'!B7 -> Gesamteindruck | C6: ='Bewertung - Nutzwert'!E7 -> 1.75 | D6: ='Bewertung - Nutzwert'!G7 -> 1.5 | E6: ='Bewertung - Nutzwert'!I7 -> 1.5 | F6: ='Bewertung - Nutzwert'!K7 -> 0 | G6: ='Bewertung - Nutzwert'!M7 -> 0
A7: ='Bewertung - Nutzwert'!A8 -> 3 | B7: ='Bewertung - Nutzwert'!B8 -> Einzelkompetenz | C7: ='Bewertung - Nutzwert'!E8 -> 1.8 | D7: ='Bewertung - Nutzwert'!G8 -> 2.4 | E7: ='Bewertung - Nutzwert'!I8 -> 2.1 | F7: ='Bewertung - Nutzwert'!K8 -> 0 | G7: ='Bewertung - Nutzwert'!M8 -> 0
A8: ='Bewertung - Nutzwert'!A9 -> 4 | B8: ='Bewertung - Nutzwert'!B9 -> Laufzeit | C8: ='Bewertung - Nutzwert'!E9 -> 0.75 | D8: ='Bewertung - Nutzwert'!G9 -> 1.05 | E8: ='Bewertung - Nutzwert'!I9 -> 0.75 | F8: ='Bewertung - Nutzwert'!K9 -> 0 | G8: ='Bewertung - Nutzwert'!M9 -> 0
A9: ='Bewertung - Nutzwert'!A10 -> 5 | B9: ='Bewertung - Nutzwert'!B10 -> Kosten/PT | C9: ='Bewertung - Nutzwert'!E10 -> 0.75 | D9: ='Bewertung - Nutzwert'!G10 -> 0.6 | E9: ='Bewertung - Nutzwert'!I10 -> 0.3 | F9: ='Bewertung - Nutzwert'!K10 -> 0 | G9: ='Bewertung - Nutzwert'!M10 -> 0
A10: ='Bewertung - Nutzwert'!A11 -> 6 | B10: ='Bewertung - Nutzwert'!B11 -> 0 | C10: ='Bewertung - Nutzwert'!E11 -> 0 | D10: ='Bewertung - Nutzwert'!G11 -> 0 | E10: ='Bewertung - Nutzwert'!I11 -> 0 | F10: ='Bewertung - Nutzwert'!K11 -> 0 | G10: ='Bewertung - Nutzwert'!M11 -> 0
A11: ='Bewertung - Nutzwert'!A12 -> 7 | B11: ='Bewertung - Nutzwert'!B12 -> 0 | C11: ='Bewertung - Nutzwert'!E12 -> 0 | D11: ='Bewertung - Nutzwert'!G12 -> 0 | E11: ='Bewertung - Nutzwert'!I12 -> 0 | F11: ='Bewertung - Nutzwert'!K12 -> 0 | G11: ='Bewertung - Nutzwert'!M12 -> 0
A12: ='Bewertung - Nutzwert'!A13 -> 8 | B12: ='Bewertung - Nutzwert'!B13 -> 0 | C12: ='Bewertung - Nutzwert'!E13 -> 0 | D12: ='Bewertung - Nutzwert'!G13 -> 0 | E12: ='Bewertung - Nutzwert'!I13 -> 0 | F12: ='Bewertung - Nutzwert'!K13 -> 0 | G12: ='Bewertung - Nutzwert'!M13 -> 0
A13: ='Bewertung - Nutzwert'!A14 -> 9 | B13: ='Bewertung - Nutzwert'!B14 -> 0 | C13: ='Bewertung - Nutzwert'!E14 -> 0 | D13: ='Bewertung - Nutzwert'!G14 -> 0 | E13: ='Bewertung - Nutzwert'!I14 -> 0 | F13: ='Bewertung - Nutzwert'!K14 -> 0 | G13: ='Bewertung - Nutzwert'!M14 -> 0
A14: ='Bewertung - Nutzwert'!A15 -> 10 | B14: ='Bewertung - Nutzwert'!B15 -> 0 | C14: ='Bewertung - Nutzwert'!E15 -> 0 | D14: ='Bewertung - Nutzwert'!G15 -> 0 | E14: ='Bewertung - Nutzwert'!I15 -> 0 | F14: ='Bewertung - Nutzwert'!K15 -> 0 | G14: ='Bewertung - Nutzwert'!M15 -> 0
