Workbook

Sheet Wochen
B1: Bewertung der Frühindikatoren
B3: 40004 | D3: Kommunikation | F3: Motivation | H3: Engagament | J3: Wohlfühlfaktor
B4: Name | D4: Einzel | E4: Team | F4: Einzel | G4: Team | H4: Einzel | I4: Team | J4: Einzel | K4: Team
B6: Meier | D6: 3 | E6: 3 | F6: 3 | G6: 3 | H6: 3 | I6: 3 | J6: 3 | K6: 3
B7: Müller | D7: 2 | E7: 3 | F7: 2 | G7: 3 | H7: 2 | I7: 3 | J7: 2 | K7: 3
B8: Huber | D8: 3 | E8: 2 | F8: 3 | G8: 2 | H8: 3 | I8: 2 | J8: 3 | K8: 2
B9: Gerber | D9: 3 | E9: 3 | F9: 3 | G9: 3 | H9: 3 | I9: 3 | J9: 3 | K9: 3
B13: 40018 | D13: Kommunikation | F13: Motivation | H13: Engagament | J13: Wohlfühlfaktor
B14: Name | D14: Einzel | E14: Team | F14: Einzel | G14: Team | H14: Einzel | I14: Team | J14: Einzel | K14: Team
B16: Meier | D16: 2 | E16: 3 | F16: 2 | G16: 3 | H16: 2 | I16: 1 | J16: 2 | K16: 3
B17: Müller | D17: 3 | E17: 2 | F17: 2 | G17: 2 | H17: 1 | I17: 2 | J17: 3 | K17: 2
B18: Huber | D18: 3 | E18: 3 | F18: 3 | G18: 3 | H18: 3 | I18: 3 | J18: 3 | K18: 3
B19: Gerber | D19: 2 | E19: 3 | F19: 2 | G19: 3 | H19: 2 | I19: 3 | J19: 2 | K19: 3
B23: 40032 | D23: Kommunikation | F23: Motivation | H23: Engagament | J23: Wohlfühlfaktor
B24: Name | D24: Einzel | E24: Team | F24: Einzel | G24: Team | H24: Einzel | I24: Team | J24: Einzel | K24: Team
B26: Meier | D26: 1 | E26: 2 | F26: 3 | G26: 2 | H26: 3 | I26: 2 | J26: 3 | K26: 2
B27: Müller | D27: 3 | E27: 3 | F27: 1 | G27: 3 | H27: 2 | I27: 3 | J27: 3 | K27: 3
B28: Huber | D28: 2 | E28: 3 | F28: 2 | G28: 3 | H28: 2 | I28: 2 | J28: 2 | K28: 3
B29: Gerber | D29: 2 | E29: 2 | F29: 2 | G29: 2 | H29: 2 | I29: 2 | J29: 2 | K29: 2
B30: Blaser | D30: 3 | E30: 3 | F30: 3 | G30: 3 | H30: 3 | I30: 3 | J30: 3 | K30: 3
B33: 40046 | D33: Kommunikation | F33: Motivation | H33: Engagament | J33: Wohlfühlfaktor
B34: Name | D34: Einzel | E34: Team | F34: Einzel | G34: Team | H34: Einzel | I34: Team | J34: Einzel | K34: Team
B36: Meier | D36: 3 | E36: 3 | F36: 3 | G36: 3 | H36: 3 | I36: 3 | J36: 3 | K36: 3
B37: Müller | D37: 2 | E37: 3 | F37: 2 | G37: 3 | H37: 1 | I37: 2 | J37: 2 | K37: 3
B38: Huber | D38: 2 | E38: 2 | F38: 2 | G38: 2 | H38: 2 | I38: 2 | J38: 2 | K38: 2
B39: Gerber | D39: 3 | E39: 3 | F39: 3 | G39: 3 | H39: 3 | I39: 3 | J39: 3 | K39: 3
B40: Blaser | D40: 2 | E40: 3 | F40: 2 | G40: 3 | H40: 2 | I40: 3 | J40: 2 | K40: 3
B41: Lüthi | D41: 3 | E41: 2 | F41: 3 | G41: 2 | H41: 3 | I41: 2 | J41: 3 | K41: 2
B43: 40060 | D43: Kommunikation | F43: Motivation | H43: Engagament | J43: Wohlfühlfaktor
B44: Name | D44: Einzel | E44: Team | F44: Einzel | G44: Team | H44: Einzel | I44: Team | J44: Einzel | K44: Team
B46: Meier | D46: 3 | E46: 3 | F46: 3 | G46: 3 | H46: 3 | I46: 3 | J46: 3 | K46: 3
B47: Müller | D47: 2 | E47: 3 | F47: 2 | G47: 3 | H47: 2 | I47: 3 | J47: 2 | K47: 3
B48: Huber | D48: 3 | E48: 2 | F48: 3 | G48: 2 | H48: 3 | I48: 2 | J48: 3 | K48: 2
B49: Gerber | D49: 3 | E49: 3 | F49: 3 | G49: 3 | H49: 3 | I49: 3 | J49: 3 | K49: 3
B50: Blaser | D50: 2 | E50: 3 | F50: 2 | G50: 3 | H50: 2 | I50: 3 | J50: 2 | K50: 3
B51: Lüthi | D51: 2 | E51: 2 | F51: 2 | G51: 2 | H51: 2 | I51: 2 | J51: 2 | K51: 2
B53: 40074 | D53: Kommunikation | F53: Motivation | H53: Engagament | J53: Wohlfühlfaktor
B54: Name | D54: Einzel | E54: Team | F54: Einzel | G54: Team | H54: Einzel | I54: Team | J54: Einzel | K54: Team
B56: Meier | D56: 2 | E56: 3 | F56: 2 | G56: 3 | H56: 2 | I56: 1 | J56: 2 | K56: 3
B57: Müller | D57: 3 | E57: 2 | F57: 2 | G57: 2 | H57: 1 | I57: 2 | J57: 3 | K57: 2
...

Sheet All
B1: Frühindikatoren - All
B3: Kommunikation
D4: Schnitt | G4: =Wochen!$B$3 -> 40004 | I4: =Wochen!$B$13 -> 40018 | K4: =Wochen!$B$23 -> 40032 | M4: =Wochen!$B$33 -> 40046 | O4: =Wochen!$B$43 -> 40060 | Q4: =Wochen!$B$53 -> 40074 | S4: =Wochen!$B$63 -> 40088 | U4: =Wochen!$B$73 -> 40102
B5: Name | D5: Einzel | E5: Team | G5: Einzel | H5: Team | I5: Einzel | J5: Team | K5: Einzel | L5: Team | M5: Einzel | N5: Team | O5: Einzel | P5: Team | Q5: Einzel | R5: Team | S5: Einzel | T5: Team | U5: Einzel | V5: Team
B7: Meier | D7: =AVERAGE(G7,I7,K7,M7,O7,Q7,S7) -> 2.1428571 | E7: =AVERAGE(H7,J7,L7,N7,P7,R7,T7) -> 2.7142857 | G7: =Wochen!D6 -> 3 | H7: =Wochen!E6 -> 3 | I7: =Wochen!D16 -> 2 | J7: =Wochen!E16 -> 3 | K7: =Wochen!D26 -> 1 | L7: =Wochen!E26 -> 2 | M7: =Wochen!D36 -> 3 | N7: =Wochen!E36 -> 3 | O7: =Wochen!D46 -> 3 | P7: =Wochen!E46 -> 3 | Q7: =Wochen!D56 -> 2 | R7: =Wochen!E56 -> 3 | S7: =Wochen!D66 -> 1 | T7: =Wochen!E66 -> 2 | U7: =Wochen!D76 -> 0 | V7: =Wochen!E76 -> 0
B8: Müller | D8: =AVERAGE(G8,I8,K8,M8,O8,Q8) -> 2.5 | E8: =AVERAGE(H8,J8,L8,N8,P8,R8) -> 2.6666667 | G8: =Wochen!D7 -> 2 | H8: =Wochen!E7 -> 3 | I8: =Wochen!D17 -> 3 | J8: =Wochen!E17 -> 2 | K8: =Wochen!D27 -> 3 | L8: =Wochen!E27 -> 3 | M8: =Wochen!D37 -> 2 | N8: =Wochen!E37 -> 3 | O8: =Wochen!D47 -> 2 | P8: =Wochen!E47 -> 3 | Q8: =Wochen!D57 -> 3 | R8: =Wochen!E57 -> 2
B9: Huber | D9: =AVERAGE(G9,I9,K9,M9,O9,Q9,S9,U9) -> 2.5 | E9: =AVERAGE(H9,J9,L9,N9,P9,R9,T9,V9) -> 2.5 | G9: =Wochen!D8 -> 3 | H9: =Wochen!E8 -> 2 | I9: =Wochen!D18 -> 3 | J9: =Wochen!E18 -> 3 | K9: =Wochen!D28 -> 2 | L9: =Wochen!E28 -> 3 | M9: =Wochen!D38 -> 2 | N9: =Wochen!E38 -> 2 | O9: =Wochen!D48 -> 3 | P9: =Wochen!E48 -> 2 | Q9: =Wochen!D58 -> 3 | R9: =Wochen!E58 -> 3 | S9: =Wochen!D68 -> 2 | T9: =Wochen!E68 -> 3 | U9: =Wochen!D78 -> 2 | V9: =Wochen!E78 -> 2
B10: Gerber | D10: =AVERAGE(G10,I10,K10,M10,O10,Q10,S10,U10) -> 2.5 | E10: =AVERAGE(H10,J10,L10,N10,P10,R10,T10,V10) -> 2.75 | G10: =Wochen!D9 -> 3 | H10: =Wochen!E9 -> 3 | I10: =Wochen!D19 -> 2 | J10: =Wochen!E19 -> 3 | K10: =Wochen!D29 -> 2 | L10: =Wochen!E29 -> 2 | M10: =Wochen!D39 -> 3 | N10: =Wochen!E39 -> 3 | O10: =Wochen!D49 -> 3 | P10: =Wochen!E49 -> 3 | Q10: =Wochen!D59 -> 2 | R10: =Wochen!E59 -> 3 | S10: =Wochen!D69 -> 2 | T10: =Wochen!E69 -> 2 | U10: =Wochen!D79 -> 3 | V10: =Wochen!E79 -> 3
B11: Blaser | D11: =AVERAGE(G11,I11,K11,M11,O11,Q11,S11,U11) -> 2.3333333 | E11: =AVERAGE(H11,J11,L11,N11,P11,R11,T11,V11) -> 2.8333333 | K11: =Wochen!D30 -> 3 | L11: =Wochen!E30 -> 3 | M11: =Wochen!D40 -> 2 | N11: =Wochen!E40 -> 3 | O11: =Wochen!D50 -> 2 | P11: =Wochen!E50 -> 3 | Q11: =Wochen!D60 -> 2 | R11: =Wochen!E60 -> 2 | S11: =Wochen!D70 -> 3 | T11: =Wochen!E70 -> 3 | U11: =Wochen!D80 -> 2 | V11: =Wochen!E80 -> 3
B12: Lüthi | D12: =AVERAGE(G12,I12,K12,M12,O12,Q12,S12,U12) -> 2.6 | E12: =AVERAGE(H12,J12,L12,N12,P12,R12,T12,V12) -> 2.4 | M12: =Wochen!D41 -> 3 | N12: =Wochen!E41 -> 2 | O12: =Wochen!D51 -> 2 | P12: =Wochen!E51 -> 2 | Q12: =Wochen!D61 -> 3 | R12: =Wochen!E61 -> 3 | S12: =Wochen!D71 -> 2 | T12: =Wochen!E71 -> 3 | U12: =Wochen!D81 -> 3 | V12: =Wochen!E81 -> 2
B14: Motivation
D15: Schnitt | G15: =Wochen!$B$3 -> 40004 | I15: =Wochen!$B$13 -> 40018 | K15: =Wochen!$B$23 -> 40032 | M15: =Wochen!$B$33 -> 40046 | O15: =Wochen!$B$43 -> 40060 | Q15: =Wochen!$B$53 -> 40074 | S15: =Wochen!$B$63 -> 40088 | U15: =Wochen!$B$73 -> 40102
B16: Name | D16: Einzel | E16: Team | G16: Einzel | H16: Team | I16: Einzel | J16: Team | K16: Einzel | L16: Team | M16: Einzel | N16: Team | O16: Einzel | P16: Team | Q16: Einzel | R16: Team | S16: Einzel | T16: Team | U16: Einzel | V16: Team
B18: Meier | D18: =AVERAGE(G18,I18,K18,M18,O18,Q18,S18) -> 2.7142857 | E18: =AVERAGE(H18,J18,L18,N18,P18,R18,T18) -> 2.7142857 | G18: =Wochen!F6 -> 3 | H18: =Wochen!G6 -> 3 | I18: =Wochen!F16 -> 2 | J18: =Wochen!G16 -> 3 | K18: =Wochen!F26 -> 3 | L18: =Wochen!G26 -> 2 | M18: =Wochen!F36 -> 3 | N18: =Wochen!G36 -> 3 | O18: =Wochen!F46 -> 3 | P18: =Wochen!G46 -> 3 | Q18: =Wochen!F56 -> 2 | R18: =Wochen!G56 -> 3 | S18: =Wochen!F66 -> 3 | T18: =Wochen!G66 -> 2 | U18: =Wochen!F76 -> 0 | V18: =Wochen!G76 -> 0
B19: Müller | D19: =AVERAGE(G19,I19,K19,M19,O19,Q19,S19,U19) -> 1.8333333 | E19: =AVERAGE(H19,J19,L19,N19,P19,R19,T19,V19) -> 2.6666667 | G19: =Wochen!F7 -> 2 | H19: =Wochen!G7 -> 3 | I19: =Wochen!F17 -> 2 | J19: =Wochen!G17 -> 2 | K19: =Wochen!F27 -> 1 | L19: =Wochen!G27 -> 3 | M19: =Wochen!F37 -> 2 | N19: =Wochen!G37 -> 3 | O19: =Wochen!F47 -> 2 | P19: =Wochen!G47 -> 3 | Q19: =Wochen!F57 -> 2 | R19: =Wochen!G57 -> 2
B20: Huber | D20: =AVERAGE(G20,I20,K20,M20,O20,Q20,S20,U20) -> 2.5 | E20: =AVERAGE(H20,J20,L20,N20,P20,R20,T20,V20) -> 2.5 | G20: =Wochen!F8 -> 3 | H20: =Wochen!G8 -> 2 | I20: =Wochen!F18 -> 3 | J20: =Wochen!G18 -> 3 | K20: =Wochen!F28 -> 2 | L20: =Wochen!G28 -> 3 | M20: =Wochen!F38 -> 2 | N20: =Wochen!G38 -> 2 | O20: =Wochen!F48 -> 3 | P20: =Wochen!G48 -> 2 | Q20: =Wochen!F58 -> 3 | R20: =Wochen!G58 -> 3 | S20: =Wochen!F68 -> 2 | T20: =Wochen!G68 -> 3 | U20: =Wochen!F78 -> 2 | V20: =Wochen!G78 -> 2
B21: Gerber | D21: =AVERAGE(G21,I21,K21,M21,O21,Q21,S21,U21) -> 2.5 | E21: =AVERAGE(H21,J21,L21,N21,P21,R21,T21,V21) -> 2.75 | G21: =Wochen!F9 -> 3 | H21: =Wochen!G9 -> 3 | I21: =Wochen!F19 -> 2 | J21: =Wochen!G19 -> 3 | K21: =Wochen!F29 -> 2 | L21: =Wochen!G29 -> 2 | M21: =Wochen!F39 -> 3 | N21: =Wochen!G39 -> 3 | O21: =Wochen!F49 -> 3 | P21: =Wochen!G49 -> 3 | Q21: =Wochen!F59 -> 2 | R21: =Wochen!G59 -> 3 | S21: =Wochen!F69 -> 2 | T21: =Wochen!G69 -> 2 | U21: =Wochen!F79 -> 3 | V21: =Wochen!G79 -> 3
B22: Blaser | D22: =AVERAGE(G22,I22,K22,M22,O22,Q22,S22,U22) -> 2.3333333 | E22: =AVERAGE(H22,J22,L22,N22,P22,R22,T22,V22) -> 2.8333333 | K22: =Wochen!F30 -> 3 | L22: =Wochen!G30 -> 3 | M22: =Wochen!F40 -> 2 | N22: =Wochen!G40 -> 3 | O22: =Wochen!F50 -> 2 | P22: =Wochen!G50 -> 3 | Q22: =Wochen!F60 -> 2 | R22: =Wochen!G60 -> 2 | S22: =Wochen!F70 -> 3 | T22: =Wochen!G70 -> 3 | U22: =Wochen!F80 -> 2 | V22: =Wochen!G80 -> 3
B23: Lüthi | D23: =AVERAGE(G23,I23,K23,M23,O23,Q23,S23,U23) -> 2.6 | E23: =AVERAGE(H23,J23,L23,N23,P23,R23,T23,V23) -> 2.4 | M23: =Wochen!F41 -> 3 | N23: =Wochen!G41 -> 2 | O23: =Wochen!F51 -> 2 | P23: =Wochen!G51 -> 2 | Q23: =Wochen!F61 -> 3 | R23: =Wochen!G61 -> 3 | S23: =Wochen!F71 -> 2 | T23: =Wochen!G71 -> 3 | U23: =Wochen!F81 -> 3 | V23: =Wochen!G81 -> 2
B25: Engagement
D26: Schnitt | G26: =Wochen!$B$3 -> 40004 | I26: =Wochen!$B$13 -> 40018 | K26: =Wochen!$B$23 -> 40032 | M26: =Wochen!$B$33 -> 40046 | O26: =Wochen!$B$43 -> 40060 | Q26: =Wochen!$B$53 -> 40074 | S26: =Wochen!$B$63 -> 40088 | U26: =Wochen!$B$73 -> 40102
B27: Name | D27: Einzel | E27: Team | G27: Einzel | H27: Team | I27: Einzel | J27: Team | K27: Einzel | L27: Team | M27: Einzel | N27: Team | O27: Einzel | P27: Team | Q27: Einzel | R27: Team | S27: Einzel | T27: Team | U27: Einzel | V27: Team
B29: Meier | D29: =AVERAGE(G29,I29,K29,M29,O29,Q29,S29) -> 2.7142857 | E29: =AVERAGE(H29,J29,L29,N29,P29,R29,T29) -> 2.1428571 | G29: =Wochen!H6 -> 3 | H29: =Wochen!I6 -> 3 | I29: =Wochen!H16 -> 2 | J29: =Wochen!I16 -> 1 | K29: =Wochen!H26 -> 3 | L29: =Wochen!I26 -> 2 | M29: =Wochen!H36 -> 3 | N29: =Wochen!I36 -> 3 | O29: =Wochen!H46 -> 3 | P29: =Wochen!I46 -> 3 | Q29: =Wochen!H56 -> 2 | R29: =Wochen!I56 -> 1 | S29: =Wochen!H66 -> 3 | T29: =Wochen!I66 -> 2 | U29: =Wochen!H76 -> 0 | V29: =Wochen!I76 -> 0
B30: Müller | D30: =AVERAGE(G30,I30,K30,M30,O30,Q30,S30,U30) -> 1.5 | E30: =AVERAGE(H30,J30,L30,N30,P30,R30,T30,V30) -> 2.5 | G30: =Wochen!H7 -> 2 | H30: =Wochen!I7 -> 3 | I30: =Wochen!H17 -> 1 | J30: =Wochen!I17 -> 2 | K30: =Wochen!H27 -> 2 | L30: =Wochen!I27 -> 3 | M30: =Wochen!H37 -> 1 | N30: =Wochen!I37 -> 2 | O30: =Wochen!J37 -> 2 | P30: =Wochen!K37 -> 3 | Q30: =Wochen!H57 -> 1 | R30: =Wochen!I57 -> 2
B31: Huber | D31: =AVERAGE(G31,I31,K31,M31,O31,Q31,S31,U31) -> 2.375 | E31: =AVERAGE(H31,J31,L31,N31,P31,R31,T31,V31) -> 2.25 | G31: =Wochen!H8 -> 3 | H31: =Wochen!I8 -> 2 | I31: =Wochen!H18 -> 3 | J31: =Wochen!I18 -> 3 | K31: =Wochen!H28 -> 2 | L31: =Wochen!I28 -> 2 | M31: =Wochen!H38 -> 2 | N31: =Wochen!I38 -> 2 | O31: =Wochen!J38 -> 2 | P31: =Wochen!K38 -> 2 | Q31: =Wochen!H58 -> 3 | R31: =Wochen!I58 -> 3 | S31: =Wochen!H68 -> 2 | T31: =Wochen!I68 -> 2 | U31: =Wochen!H78 -> 2 | V31: =Wochen!I78 -> 2
B32: Gerber | D32: =AVERAGE(G32,I32,K32,M32,O32,Q32,S32,U32) -> 2.5 | E32: =AVERAGE(H32,J32,L32,N32,P32,R32,T32,V32) -> 2.75 | G32: =Wochen!H9 -> 3 | H32: =Wochen!I9 -> 3 | I32: =Wochen!H19 -> 2 | J32: =Wochen!I19 -> 3 | K32: =Wochen!H29 -> 2 | L32: =Wochen!I29 -> 2 | M32: =Wochen!H39 -> 3 | N32: =Wochen!I39 -> 3 | O32: =Wochen!J39 -> 3 | P32: =Wochen!K39 -> 3 | Q32: =Wochen!H59 -> 2 | R32: =Wochen!I59 -> 3 | S32: =Wochen!H69 -> 2 | T32: =Wochen!I69 -> 2 | U32: =Wochen!H79 -> 3 | V32: =Wochen!I79 -> 3
B33: Blaser | D33: =AVERAGE(G33,I33,K33,M33,O33,Q33,S33,U33) -> 2.3333333 | E33: =AVERAGE(H33,J33,L33,N33,P33,R33,T33,V33) -> 2.8333333 | K33: =Wochen!H30 -> 3 | L33: =Wochen!I30 -> 3 | M33: =Wochen!H40 -> 2 | N33: =Wochen!I40 -> 3 | O33: =Wochen!J40 -> 2 | P33: =Wochen!K40 -> 3 | Q33: =Wochen!H60 -> 2 | R33: =Wochen!I60 -> 2 | S33: =Wochen!H70 -> 3 | T33: =Wochen!I70 -> 3 | U33: =Wochen!H80 -> 2 | V33: =Wochen!I80 -> 3
B34: Lüthi | D34: =AVERAGE(G34,I34,K34,M34,O34,Q34,S34,U34) -> 2.8 | E34: =AVERAGE(H34,J34,L34,N34,P34,R34,T34,V34) -> 2.4 | M34: =Wochen!H41 -> 3 | N34: =Wochen!I41 -> 2 | O34: =Wochen!J41 -> 3 | P34: =Wochen!K41 -> 2 | Q34: =Wochen!H61 -> 3 | R34: =Wochen!I61 -> 3 | S34: =Wochen!H71 -> 2 | T34: =Wochen!I71 -> 3 | U34: =Wochen!H81 -> 3 | V34: =Wochen!I81 -> 2
B36: Wohlfühlfaktor
D37: Schnitt | G37: =Wochen!$B$3 -> 40004 | I37: =Wochen!$B$13 -> 40018 | K37: =Wochen!$B$23 -> 40032 | M37: =Wochen!$B$33 -> 40046 | O37: =Wochen!$B$43 -> 40060 | Q37: =Wochen!$B$53 -> 40074 | S37: =Wochen!$B$63 -> 40088 | U37: =Wochen!$B$73 -> 40102
B38: Name | D38: Einzel | E38: Team | G38: Einzel | H38: Team | I38: Einzel | J38: Team | K38: Einzel | L38: Team | M38: Einzel | N38: Team | O38: Einzel | P38: Team | Q38: Einzel | R38: Team | S38: Einzel | T38: Team | U38: Einzel | V38: Team
B40: Meier | D40: =AVERAGE(G40,I40,K40,M40,O40,Q40,S40) -> 2.7142857 | E40: =AVERAGE(H40,J40,L40,N40,P40,R40,T40) -> 2.7142857 | G40: =Wochen!J6 -> 3 | H40: =Wochen!K6 -> 3 | I40: =Wochen!J16 -> 2 | J40: =Wochen!K16 -> 3 | K40: =Wochen!J26 -> 3 | L40: =Wochen!K26 -> 2 | M40: =Wochen!J36 -> 3 | N40: =Wochen!K36 -> 3 | O40: =Wochen!J46 -> 3 | P40: =Wochen!K46 -> 3 | Q40: =Wochen!J56 -> 2 | R40: =Wochen!K56 -> 3 | S40: =Wochen!J66 -> 3 | T40: =Wochen!K66 -> 2 | U40: =Wochen!J76 -> 0 | V40: =Wochen!K76 -> 0
B41: Müller | D41: =AVERAGE(G41,I41,K41,M41,O41,Q41,S41,U41) -> 2.5 | E41: =AVERAGE(H41,J41,L41,N41,P41,R41,T41,V41) -> 2.6666667 | G41: =Wochen!J7 -> 2 | H41: =Wochen!K7 -> 3 | I41: =Wochen!J17 -> 3 | J41: =Wochen!K17 -> 2 | K41: =Wochen!J27 -> 3 | L41: =Wochen!K27 -> 3 | M41: =Wochen!J37 -> 2 | N41: =Wochen!K37 -> 3 | O41: =Wochen!J47 -> 2 | P41: =Wochen!K47 -> 3 | Q41: =Wochen!J57 -> 3 | R41: =Wochen!K57 -> 2
B42: Huber | D42: =AVERAGE(G42,I42,K42,M42,O42,Q42,S42,U42) -> 2.5 | E42: =AVERAGE(H42,J42,L42,N42,P42,R42,T42,V42) -> 2.5 | G42: =Wochen!J8 -> 3 | H42: =Wochen!K8 -> 2 | I42: =Wochen!J18 -> 3 | J42: =Wochen!K18 -> 3 | K42: =Wochen!J28 -> 2 | L42: =Wochen!K28 -> 3 | M42: =Wochen!J38 -> 2 | N42: =Wochen!K38 -> 2 | O42: =Wochen!J48 -> 3 | P42: =Wochen!K48 -> 2 | Q42: =Wochen!J58 -> 3 | R42: =Wochen!K58 -> 3 | S42: =Wochen!J68 -> 2 | T42: =Wochen!K68 -> 3 | U42: =Wochen!J78 -> 2 | V42: =Wochen!K78 -> 2
B43: Gerber | D43: =AVERAGE(G43,I43,K43,M43,O43,Q43,S43,U43) -> 2.5 | E43: =AVERAGE(H43,J43,L43,N43,P43,R43,T43,V43) -> 2.75 | G43: =Wochen!J9 -> 3 | H43: =Wochen!K9 -> 3 | I43: =Wochen!J19 -> 2 | J43: =Wochen!K19 -> 3 | K43: =Wochen!J29 -> 2 | L43: =Wochen!K29 -> 2 | M43: =Wochen!J39 -> 3 | N43: =Wochen!K39 -> 3 | O43: =Wochen!J49 -> 3 | P43: =Wochen!K49 -> 3 | Q43: =Wochen!J59 -> 2 | R43: =Wochen!K59 -> 3 | S43: =Wochen!J69 -> 2 | T43: =Wochen!K69 -> 2 | U43: =Wochen!J79 -> 3 | V43: =Wochen!K79 -> 3
B44: Blaser | D44: =AVERAGE(G44,I44,K44,M44,O44,Q44,S44,U44) -> 2.3333333 | E44: =AVERAGE(H44,J44,L44,N44,P44,R44,T44,V44) -> 2.8333333 | K44: =Wochen!J30 -> 3 | L44: =Wochen!K30 -> 3 | M44: =Wochen!J40 -> 2 | N44: =Wochen!K40 -> 3 | O44: =Wochen!J50 -> 2 | P44: =Wochen!K50 -> 3 | Q44: =Wochen!J60 -> 2 | R44: =Wochen!K60 -> 2 | S44: =Wochen!J70 -> 3 | T44: =Wochen!K70 -> 3 | U44: =Wochen!J80 -> 2 | V44: =Wochen!K80 -> 3
B45: Lüthi | D45: =AVERAGE(G45,I45,K45,M45,O45,Q45,S45,U45) -> 2.6 | E45: =AVERAGE(H45,J45,L45,N45,P45,R45,T45,V45) -> 2.4 | M45: =Wochen!J41 -> 3 | N45: =Wochen!K41 -> 2 | O45: =Wochen!J51 -> 2 | P45: =Wochen!K51 -> 2 | Q45: =Wochen!J61 -> 3 | R45: =Wochen!K61 -> 3 | S45: =Wochen!J71 -> 2 | T45: =Wochen!K71 -> 3 | U45: =Wochen!J81 -> 3 | V45: =Wochen!K81 -> 2
